Workbook

Sheet 📈 Equities IPO's
A1: 📈 New IPO Listings Since Nepse low of 1,815.13 ( 2022-09-25)— Performance Tracker
A2: ="Sorted oldest → newest · "&COUNTA(A4:A79)&" equity listings · As of "&TEXT(TODAY(),"MMM DD, YYYY")&" · Base investment NPR 100,000" -> Sorted oldest → newest · 76 equity listings · As of May 10, 2026 · Base investment NPR 100,000
A3: # | B3: Symbol | C3: Company Name | D3: Listing Date | E3: Time Since IPO | F3: Start Price (NPR) | G3: Current Price (NPR) | H3: Multiple | I3: CAGR (%) | J3: Current Value (NPR) | K3: Years | L3: TrueCAGR
A4: =IF(B4<>"",ROW()-3,"") -> 1 | B4: PPL | C4: People Power Company Ltd | D4: 2022-10-16 | E4: 3.6 yrs | F4: 255.7 | G4: 345 | H4: 1.69x | I4: 15.9% | J4: 202385.61 | K4: =IFERROR((TODAY()-DATEVALUE(D4))/365.25,"") -> 3.5646817 | L4: =IFERROR(IF(K4>=0.25,(G4/F4)^(1/K4)-1,"<3mo"),"") -> 0.087661319
A5: =IF(B5<>"",ROW()-3,"") -> 2 | B5: SPHL | C5: Sayapatri Hydropower Ltd | D5: 2022-10-17 | E5: 3.6 yrs | F5: 214.2 | G5: 512 | H5: 2.39x | I5: 27.8% | J5: 239028.94 | K5: =IFERROR((TODAY()-DATEVALUE(D5))/365.25,"") -> 3.5619439 | L5: =IFERROR(IF(K5>=0.25,(G5/F5)^(1/K5)-1,"<3mo"),"") -> 0.27716881
A6: =IF(B6<>"",ROW()-3,"") -> 3 | B6: SIKLES | C6: Sikles Hydropower Ltd | D6: 2022-11-15 | E6: 3.5 yrs | F6: 321 | G6: 577.9 | H6: 2.12x | I6: 24.2% | J6: 212429.91 | K6: =IFERROR((TODAY()-DATEVALUE(D6))/365.25,"") -> 3.4825462 | L6: =IFERROR(IF(K6>=0.25,(G6/F6)^(1/K6)-1,"<3mo"),"") -> 0.18391935
A7: =IF(B7<>"",ROW()-3,"") -> 4 | B7: EHPL | C7: Earthmovers Hydropower Ltd | D7: 2022-12-14 | E7: 3.4 yrs | F7: 237.6 | G7: 384 | H7: 1.62x | I7: 15.2% | J7: 161616.16 | K7: =IFERROR((TODAY()-DATEVALUE(D7))/365.25,"") -> 3.4031485 | L7: =IFERROR(IF(K7>=0.25,(G7/F7)^(1/K7)-1,"<3mo"),"") -> 0.15149571
A8: =IF(B8<>"",ROW()-3,"") -> 5 | B8: PHCL | C8: Pathivara Hydropower Company Ltd | D8: 2022-12-14 | E8: 3.4 yrs | F8: 270 | G8: 307.9 | H8: 1.14x | I8: 3.9% | J8: 114037.04 | K8: =IFERROR((TODAY()-DATEVALUE(D8))/365.25,"") -> 3.4031485 | L8: =IFERROR(IF(K8>=0.25,(G8/F8)^(1/K8)-1,"<3mo"),"") -> 0.039352082
A9: =IF(B9<>"",ROW()-3,"") -> 6 | B9: SHLB | C9: Shrijanshil Laghubitta Bittiya Sanstha | D9: 2022-12-20 | E9: 3.4 yrs | F9: 996.6 | G9: 1490 | H9: 1.50x | I9: 12.6% | J9: 149508.33 | K9: =IFERROR((TODAY()-DATEVALUE(D9))/365.25,"") -> 3.3867214 | L9: =IFERROR(IF(K9>=0.25,(G9/F9)^(1/K9)-1,"<3mo"),"") -> 0.12609127
A10: =IF(B10<>"",ROW()-3,"") -> 7 | B10: BHPL | C10: Barun Hydropower Ltd | D10: 2023-01-04 | E10: 3.3 yrs | F10: 213.7 | G10: 520 | H10: 2.43x | I10: 30.5% | J10: 243331.77 | K10: =IFERROR((TODAY()-DATEVALUE(D10))/365.25,"") -> 3.3456537 | L10: =IFERROR(IF(K10>=0.25,(G10/F10)^(1/K10)-1,"<3mo"),"") -> 0.30446669
A11: =IF(B11<>"",ROW()-3,"") -> 8 | B11: SJLIC | C11: SuryaJyoti Life Insurance Company Ltd | D11: 2023-01-25 | E11: 3.3 yrs | F11: 408.7 | G11: 431.3 | H11: 1.31x | I11: 8.7% | J11: 131313.23 | K11: =IFERROR((TODAY()-DATEVALUE(D11))/365.25,"") -> 3.2881588 | L11: =IFERROR(IF(K11>=0.25,(G11/F11)^(1/K11)-1,"<3mo"),"") -> 0.016503286
A12: =IF(B12<>"",ROW()-3,"") -> 9 | B12: SMHL | C12: Samaj Microfinance Ltd | D12: 2023-03-05 | E12: 3.2 yrs | F12: 328.9 | G12: 497.6 | H12: 1.68x | I12: 17.6% | J12: 167570.8 | K12: =IFERROR((TODAY()-DATEVALUE(D12))/365.25,"") -> 3.1813826 | L12: =IFERROR(IF(K12>=0.25,(G12/F12)^(1/K12)-1,"<3mo"),"") -> 0.13899415
A13: =IF(B13<>"",ROW()-3,"") -> 10 | B13: SPL | C13: Seti Power Ltd | D13: 2023-03-07 | E13: 3.2 yrs | F13: 291.5 | G13: 700 | H13: 2.40x | I13: 31.8% | J13: 240137.22 | K13: =IFERROR((TODAY()-DATEVALUE(D13))/365.25,"") -> 3.1759069 | L13: =IFERROR(IF(K13>=0.25,(G13/F13)^(1/K13)-1,"<3mo"),"") -> 0.31763626
A14: =IF(B14<>"",ROW()-3,"") -> 11 | B14: MKHC | C14: Maya Khola Hydropower Company | D14: 2023-03-22 | E14: 3.1 yrs | F14: 292 | G14: 316 | H14: 1.08x | I14: 2.6% | J14: 108219.18 | K14: =IFERROR((TODAY()-DATEVALUE(D14))/365.25,"") -> 3.1348392 | L14: =IFERROR(IF(K14>=0.25,(G14/F14)^(1/K14)-1,"<3mo"),"") -> 0.025517085
A15: =IF(B15<>"",ROW()-3,"") -> 12 | B15: AHL | C15: Arun Hydropower Ltd | D15: 2023-03-23 | E15: 3.1 yrs | F15: 328.6 | G15: 524 | H15: 1.59x | I15: 16.1% | J15: 159464.39 | K15: =IFERROR((TODAY()-DATEVALUE(D15))/365.25,"") -> 3.1321013 | L15: =IFERROR(IF(K15>=0.25,(G15/F15)^(1/K15)-1,"<3mo"),"") -> 0.1606609
... A79: =IF(B79<>"",ROW()-3,"") -> 76 | B79: RSML | C79: Ratna Sagar Microfinance Ltd | D79: 2026-02-16 | E79: 0 mo | F79: 330 | G79: 361.8 | H79: 1.10x | I79: >99,999% | J79: 109636.36 | K79: =IFERROR((TODAY()-DATEVALUE(D79))/365.25,"") -> 0.22724162 | L79: =IFERROR(IF(K79>=0.25,(G79/F79)^(1/K79)-1,"<3mo"),"") -> <3mo
A81: {="Equities: "&COUNTA(B4:B79)&" · Avg CAGR (time-wtd): "&TEXT(SUMPRODUCT(((TODAY()-DATEVALUE(D4:D79))/365.25>=0.1)*((G4:G79/F4:F79)^(1/MAX((TODAY()-DATEVALUE(D4:D79))/365.25,0.1))-1))/SUMPRODUCT(((TODAY()-DATEVALUE(D4:D79))/365.25>=0.1)*1),"0.0%")} -> Equities: 76 · Avg CAGR (time-wtd): 19.2%

Sheet 📊 IPO Analysis
A1: IPO Performance Analysis — CAGR vs Holding Period | N1: Bucket | O1: Median CAGR
A2: As of 2026-05-09 · 76 IPO listings analyzed · Source: '📈 Equities IPO's' | N2: 0.5-1 yr | O2: =F8 -> 1.1880503
N3: 1-1.5 yrs | O3: =F9 -> 1.9815762
A4: Holding Period Buckets | N4: 1.5-2 yrs | O4: =F10 -> -0.1717826
N5: 2-2.5 yrs | O5: =F11 -> 0.2987505
A6: Bucket | B6: Min Yrs | C6: Max Yrs | D6: # IPOs | E6: Avg CAGR | F6: Median CAGR | G6: Min CAGR | H6: Max CAGR | N6: 2.5-3 yrs | O6: =F12 -> 0.066259463
A7: < 0.5 yr (very recent) | B7: 0.25 | C7: 0.5 | D7: =COUNTIFS('📈 Equities IPO''s'!$K$4:$K$79,">="&B7,'📈 Equities IPO''s'!$K$4:$K$79,"<"&C7) -> 7 | E7: =IFERROR(AVERAGEIFS('📈 Equities IPO''s'!$L$4:$L$79,'📈 Equities IPO''s'!$K$4:$K$79,">="&B7,'📈 Equities IPO''s'!$K$4:$K$79,"<"&C7),"") -> 22.038652 | F7: {=IFERROR(IF(D7>0,_xlfn.AGGREGATE(17,6,'📈 Equities IPO''s'!$L$4:$L$79/(('📈 Equities IPO''s'!$K$4:$K$79>=B7)*('📈 Equities IPO''s'!$K$4:$K$79<C7)),2),""),"")} -> 23.475928 | G7: =IFERROR(_xlfn.MINIFS('📈 Equities IPO''s'!$L$4:$L$79,'📈 Equities IPO''s'!$K$4:$K$79,">="&B7,'📈 Equities IPO''s'!$K$4:$K$79,"<"&C7),"") -> 1.9561139 | H7: =IFERROR(_xlfn.MAXIFS('📈 Equities IPO''s'!$L$4:$L$79,'📈 Equities IPO''s'!$K$4:$K$79,">="&B7,'📈 Equities IPO''s'!$K$4:$K$79,"<"&C7),"") -> 39.814213 | N7: 3-3.5 yrs | O7: =F13 -> 0.14524493
A8: 0.5 – 1 yr | B8: 0.5 | C8: 1 | D8: =COUNTIFS('📈 Equities IPO''s'!$K$4:$K$79,">="&B8,'📈 Equities IPO''s'!$K$4:$K$79,"<"&C8) -> 8 | E8: =IFERROR(AVERAGEIFS('📈 Equities IPO''s'!$L$4:$L$79,'📈 Equities IPO''s'!$K$4:$K$79,">="&B8,'📈 Equities IPO''s'!$K$4:$K$79,"<"&C8),"") -> 1.7380473 | F8: {=IFERROR(IF(D8>0,_xlfn.AGGREGATE(17,6,'📈 Equities IPO''s'!$L$4:$L$79/(('📈 Equities IPO''s'!$K$4:$K$79>=B8)*('📈 Equities IPO''s'!$K$4:$K$79<C8)),2),""),"")} -> 1.1880503 | G8: =IFERROR(_xlfn.MINIFS('📈 Equities IPO''s'!$L$4:$L$79,'📈 Equities IPO''s'!$K$4:$K$79,">="&B8,'📈 Equities IPO''s'!$K$4:$K$79,"<"&C8),"") -> 0.13536252 | H8: =IFERROR(_xlfn.MAXIFS('📈 Equities IPO''s'!$L$4:$L$79,'📈 Equities IPO''s'!$K$4:$K$79,">="&B8,'📈 Equities IPO''s'!$K$4:$K$79,"<"&C8),"") -> 4.9384758 | N8: 3.5+ yrs | O8: =F14 -> 0.18241506
A9: 1 – 1.5 yrs | B9: 1 | C9: 1.5 | D9: =COUNTIFS('📈 Equities IPO''s'!$K$4:$K$79,">="&B9,'📈 Equities IPO''s'!$K$4:$K$79,"<"&C9) -> 4 | E9: =IFERROR(AVERAGEIFS('📈 Equities IPO''s'!$L$4:$L$79,'📈 Equities IPO''s'!$K$4:$K$79,">="&B9,'📈 Equities IPO''s'!$K$4:$K$79,"<"&C9),"") -> 2.1472296 | F9: {=IFERROR(IF(D9>0,_xlfn.AGGREGATE(17,6,'📈 Equities IPO''s'!$L$4:$L$79/(('📈 Equities IPO''s'!$K$4:$K$79>=B9)*('📈 Equities IPO''s'!$K$4:$K$79<C9)),2),""),"")} -> 1.9815762 | G9: =IFERROR(_xlfn.MINIFS('📈 Equities IPO''s'!$L$4:$L$79,'📈 Equities IPO''s'!$K$4:$K$79,">="&B9,'📈 Equities IPO''s'!$K$4:$K$79,"<"&C9),"") -> 1.7691975 | H9: =IFERROR(_xlfn.MAXIFS('📈 Equities IPO''s'!$L$4:$L$79,'📈 Equities IPO''s'!$K$4:$K$79,">="&B9,'📈 Equities IPO''s'!$K$4:$K$79,"<"&C9),"") -> 2.8565686
A10: 1.5 – 2 yrs | B10: 1.5 | C10: 2 | D10: =COUNTIFS('📈 Equities IPO''s'!$K$4:$K$79,">="&B10,'📈 Equities IPO''s'!$K$4:$K$79,"<"&C10) -> 3 | E10: =IFERROR(AVERAGEIFS('📈 Equities IPO''s'!$L$4:$L$79,'📈 Equities IPO''s'!$K$4:$K$79,">="&B10,'📈 Equities IPO''s'!$K$4:$K$79,"<"&C10),"") -> -0.14188146 | F10: {=IFERROR(IF(D10>0,_xlfn.AGGREGATE(17,6,'📈 Equities IPO''s'!$L$4:$L$79/(('📈 Equities IPO''s'!$K$4:$K$79>=B10)*('📈 Equities IPO''s'!$K$4:$K$79<C10)),2),""),"")} -> -0.1717826 | G10: =IFERROR(_xlfn.MINIFS('📈 Equities IPO''s'!$L$4:$L$79,'📈 Equities IPO''s'!$K$4:$K$79,">="&B10,'📈 Equities IPO''s'!$K$4:$K$79,"<"&C10),"") -> -0.22638619 | H10: =IFERROR(_xlfn.MAXIFS('📈 Equities IPO''s'!$L$4:$L$79,'📈 Equities IPO''s'!$K$4:$K$79,">="&B10,'📈 Equities IPO''s'!$K$4:$K$79,"<"&C10),"") -> -0.027475593
A11: 2 – 2.5 yrs | B11: 2 | C11: 2.5 | D11: =COUNTIFS('📈 Equities IPO''s'!$K$4:$K$79,">="&B11,'📈 Equities IPO''s'!$K$4:$K$79,"<"&C11) -> 8 | E11: =IFERROR(AVERAGEIFS('📈 Equities IPO''s'!$L$4:$L$79,'📈 Equities IPO''s'!$K$4:$K$79,">="&B11,'📈 Equities IPO''s'!$K$4:$K$79,"<"&C11),"") -> 0.26608632 | F11: {=IFERROR(IF(D11>0,_xlfn.AGGREGATE(17,6,'📈 Equities IPO''s'!$L$4:$L$79/(('📈 Equities IPO''s'!$K$4:$K$79>=B11)*('📈 Equities IPO''s'!$K$4:$K$79<C11)),2),""),"")} -> 0.2987505 | G11: =IFERROR(_xlfn.MINIFS('📈 Equities IPO''s'!$L$4:$L$79,'📈 Equities IPO''s'!$K$4:$K$79,">="&B11,'📈 Equities IPO''s'!$K$4:$K$79,"<"&C11),"") -> -0.090916084 | H11: =IFERROR(_xlfn.MAXIFS('📈 Equities IPO''s'!$L$4:$L$79,'📈 Equities IPO''s'!$K$4:$K$79,">="&B11,'📈 Equities IPO''s'!$K$4:$K$79,"<"&C11),"") -> 0.68785382
A12: 2.5 – 3 yrs | B12: 2.5 | C12: 3 | D12: =COUNTIFS('📈 Equities IPO''s'!$K$4:$K$79,">="&B12,'📈 Equities IPO''s'!$K$4:$K$79,"<"&C12) -> 24 | E12: =IFERROR(AVERAGEIFS('📈 Equities IPO''s'!$L$4:$L$79,'📈 Equities IPO''s'!$K$4:$K$79,">="&B12,'📈 Equities IPO''s'!$K$4:$K$79,"<"&C12),"") -> 0.12686891 | F12: {=IFERROR(IF(D12>0,_xlfn.AGGREGATE(17,6,'📈 Equities IPO''s'!$L$4:$L$79/(('📈 Equities IPO''s'!$K$4:$K$79>=B12)*('📈 Equities IPO''s'!$K$4:$K$79<C12)),2),""),"")} -> 0.066259463 | G12: =IFERROR(_xlfn.MINIFS('📈 Equities IPO''s'!$L$4:$L$79,'📈 Equities IPO''s'!$K$4:$K$79,">="&B12,'📈 Equities IPO''s'!$K$4:$K$79,"<"&C12),"") -> -0.09846978 | H12: =IFERROR(_xlfn.MAXIFS('📈 Equities IPO''s'!$L$4:$L$79,'📈 Equities IPO''s'!$K$4:$K$79,">="&B12,'📈 Equities IPO''s'!$K$4:$K$79,"<"&C12),"") -> 0.48541512
A13: 3 – 3.5 yrs | B13: 3 | C13: 3.5 | D13: =COUNTIFS('📈 Equities IPO''s'!$K$4:$K$79,">="&B13,'📈 Equities IPO''s'!$K$4:$K$79,"<"&C13) -> 18 | E13: =IFERROR(AVERAGEIFS('📈 Equities IPO''s'!$L$4:$L$79,'📈 Equities IPO''s'!$K$4:$K$79,">="&B13,'📈 Equities IPO''s'!$K$4:$K$79,"<"&C13),"") -> 0.25029702 | F13: {=IFERROR(IF(D13>0,_xlfn.AGGREGATE(17,6,'📈 Equities IPO''s'!$L$4:$L$79/(('📈 Equities IPO''s'!$K$4:$K$79>=B13)*('📈 Equities IPO''s'!$K$4:$K$79<C13)),2),""),"")} -> 0.14524493 | G13: =IFERROR(_xlfn.MINIFS('📈 Equities IPO''s'!$L$4:$L$79,'📈 Equities IPO''s'!$K$4:$K$79,">="&B13,'📈 Equities IPO''s'!$K$4:$K$79,"<"&C13),"") -> 0.016503286 | H13: =IFERROR(_xlfn.MAXIFS('📈 Equities IPO''s'!$L$4:$L$79,'📈 Equities IPO''s'!$K$4:$K$79,">="&B13,'📈 Equities IPO''s'!$K$4:$K$79,"<"&C13),"") -> 1.3856937
A14: 3.5+ yrs | B14: 3.5 | C14: 99 | D14: =COUNTIFS('📈 Equities IPO''s'!$K$4:$K$79,">="&B14,'📈 Equities IPO''s'!$K$4:$K$79,"<"&C14) -> 2 | E14: =IFERROR(AVERAGEIFS('📈 Equities IPO''s'!$L$4:$L$79,'📈 Equities IPO''s'!$K$4:$K$79,">="&B14,'📈 Equities IPO''s'!$K$4:$K$79,"<"&C14),"") -> 0.18241506 | F14: {=IFERROR(IF(D14>0,_xlfn.AGGREGATE(17,6,'📈 Equities IPO''s'!$L$4:$L$79/(('📈 Equities IPO''s'!$K$4:$K$79>=B14)*('📈 Equities IPO''s'!$K$4:$K$79<C14)),2),""),"")} -> 0.18241506 | G14: =IFERROR(_xlfn.MINIFS('📈 Equities IPO''s'!$L$4:$L$79,'📈 Equities IPO''s'!$K$4:$K$79,">="&B14,'📈 Equities IPO''s'!$K$4:$K$79,"<"&C14),"") -> 0.087661319 | H14: =IFERROR(_xlfn.MAXIFS('📈 Equities IPO''s'!$L$4:$L$79,'📈 Equities IPO''s'!$K$4:$K$79,">="&B14,'📈 Equities IPO''s'!$K$4:$K$79,"<"&C14),"") -> 0.27716881
A16: ⚠ Note: CAGR for very recent listings (<1 yr) annualizes short-period returns and produces extreme values. The "sweet spot" comparison below uses the more reliable 1+ year cohort.
A18: Statistical Analysis (cohort: 1+ yr listings, n=59)
A20: Metric | B20: Value | C20: Interpretation
A21: Sample size (n) | B21: =COUNTIFS('📈 Equities IPO''s'!$K$4:$K$79,">=1") -> 59 | C21: IPOs with ≥1 yr of trading history
A22: Mean CAGR | B22: =AVERAGEIFS('📈 Equities IPO''s'!$L$4:$L$79,'📈 Equities IPO''s'!$K$4:$K$79,">=1") -> 0.30859313 | C22: Average annualized return across cohort
A23: Median CAGR | B23: {=_xlfn.AGGREGATE(17,6,'📈 Equities IPO''s'!$L$4:$L$79/('📈 Equities IPO''s'!$K$4:$K$79>=1),2)} -> 0.15149571 | C23: Typical IPO outcome (less skewed by outliers)
A24: Std deviation | B24: {=_xlfn.STDEV.S(IF('📈 Equities IPO''s'!$K$4:$K$79>=1,'📈 Equities IPO''s'!$L$4:$L$79))} -> 0.56718768 | C24: Spread of returns — volatility across IPOs
A25: Correlation: Years vs CAGR | B25: {=CORREL(IF('📈 Equities IPO''s'!$K$4:$K$79>=1,'📈 Equities IPO''s'!$K$4:$K$79),IF('📈 Equities IPO''s'!$K$4:$K$79>=1,'📈 Equities IPO''s'!$L$4:$L$79))} -> -0.60880815 | C25: Negative = older IPOs trend lower CAGR; closer to -1 is stronger
A26: Loss rate | B26: {=SUMPRODUCT(--('📈 Equities IPO''s'!$G$4:$G$79<'📈 Equities IPO''s'!$F$4:$F$79))/COUNTA('📈 Equities IPO''s'!$B$4:$B$79)} -> 0.15789474 | C26: Share of all 76 IPOs trading below issue price today
A27: Median holding | B27: =_xlfn.AGGREGATE(17,6,'📈 Equities IPO''s'!$K$4:$K$79,2) -> 2.6146475 | C27: Median time-since-listing across the dataset
A29: Best & Worst Holding-Period Buckets
A31: Best bucket (by median CAGR, excl. <1 yr) | B31: =INDEX(A9:A14,MATCH(MAX(F9:F14),F9:F14,0)) -> 1 – 1.5 yrs | C31: Median CAGR: | D31: =MAX(F9:F14) -> 1.9815762
A32: Worst bucket (by median CAGR, excl. <1 yr) | B32: =INDEX(A9:A14,MATCH(MIN(F9:F14),F9:F14,0)) -> 1.5 – 2 yrs | C32: Median CAGR: | D32: =MIN(F9:F14) -> -0.1717826
A33: Spread (best vs worst) | B33: =D31-D32 -> 2.1533588
A35: Key Findings
A37: 1 | B37: Newer IPOs are massively outperforming. The <1 yr cohort shows extreme annualized returns (driven by recent listings doubling/tripling within months). Even normalized, the 1–1.5 yr bucket leads with median CAGR of ~199%.
A38: 2 | B38: The 1.5–2 yr cohort is the worst-performing: 3 of 3 IPOs in that bucket are below issue price (MATRI, SMPDA, NMLBBL). All three are microfinance issuers — sector concentration risk.
A39: 3 | B39: Negative correlation (-0.61) between holding period and CAGR confirms the pattern: the longer an IPO has been listed, the lower its annualized return. Recent NEPSE rally is lifting newer issues disproportionately.
A40: 4 | B40: Insurance & microfinance IPOs dominate the loss list: 7 of 12 losers are life-insurance, 3 are microfinance. Hydropower IPOs have a near-zero failure rate in this dataset.
A41: 5 | B41: Loss rate is 15.8% (12 of 76). Headline mean CAGR of 30.9% (1+ yr cohort) overstates the median experience of 15.2% — a few large winners (KDL, ANLB, recent listings) skew the average upward.
A64: Strategy Conclusions
A66: Q: | B66: Should you buy IPOs and sell at 6 months to maximize expected returns?
A67: A: | B67: No. The high CAGRs in the <1 yr cohort are a math artifact of annualizing very short holding periods (a 3-month 3.7x becomes a "38,000% CAGR"), not a repeatable edge. The real sweet spot is 2–3 years.
A69: Recommended Holding Window
A70: ✅ Sweet spot: | B70: 2 to 3 years post-listing. n=32, median CAGR ~25%, large enough sample to be reliable, low loss rate, and stocks haven't yet entered the post-3yr decay zone.
A71: ⚠ Avoid: | B71: Holding past 3 years — median CAGR drops to ~3%. Returns compress meaningfully (correlation −0.61 between holding period and CAGR confirms this is structural, not noise).
...

Sheet 🟣 Mutual Funds
A1: 🟣 NEPSE New Listings — Mutual Fund Performance Tracker
A2: Sorted oldest → newest · 21 mutual fund listings · As of May 09, 2026 · Base investment NPR 100,000
A3: # | B3: Symbol | C3: Fund Name | D3: Listing Date | E3: Time Since IPO | F3: Start Price (NPR) | G3: Current Price (NPR) | H3: Multiple | I3: CAGR (%) | J3: Current Value (NPR)
A4: 1 | B4: GIBF1 | C4: Global IME Balance Fund I | D4: 2022-09-28 | E4: 3.6 yrs | F4: 9 | G4: 10.8 | H4: 3.64x | I4: 43.1% | J4: 364444.44
A5: 2 | B5: SAGF | C5: Siddhartha Ambition Growth Fund | D5: 2023-03-15 | E5: 3.1 yrs | F5: 10 | G5: 10.15 | H5: 3.59x | I5: 50.1% | J5: 359400
A6: 3 | B6: NSIF2 | C6: NMB Sulav Investment Fund II | D6: 2023-04-03 | E6: 3.1 yrs | F6: 10 | G6: 10.98 | H6: 3.60x | I6: 51.2% | J6: 359800
A7: 4 | B7: SFEF | C7: Sunrise Focused Equity Fund | D7: 2023-04-20 | E7: 3.0 yrs | F7: 10 | G7: 10 | H7: 2.80x | I7: 40.2% | J7: 280000
A8: 5 | B8: NIBLGF | C8: NIBL Growth Fund | D8: 2023-04-27 | E8: 3.0 yrs | F8: 9 | G8: 9.57 | H8: 2.88x | I8: 41.8% | J8: 288000
A9: 6 | B9: PRSF | C9: Prabhu Rising Star Fund | D9: 2023-06-08 | E9: 2.9 yrs | F9: 9.81 | G9: 12.97 | H9: 3.21x | I9: 49.1% | J9: 320795.11
A10: 7 | B10: RMF2 | C10: Rastriya Mutual Fund II | D10: 2023-07-30 | E10: 2.8 yrs | F10: 9.85 | G10: 10.2 | H10: 3.24x | I10: 52.9% | J10: 324263.96
A11: 8 | B11: C30MF | C11: Citizens Mutual Fund 30 | D11: 2023-08-14 | E11: 2.7 yrs | F11: 9.81 | G11: 10.06 | H11: 3.34x | I11: 55.6% | J11: 334454.64
A12: 9 | B12: LVF2 | C12: Laxmi Value Fund II | D12: 2023-09-21 | E12: 2.6 yrs | F12: 10 | G12: 9.51 | H12: 2.90x | I12: 50.0% | J12: 290100
A13: 10 | B13: SIGS3 | C13: Sanima Growth Scheme III | D13: 2024-01-04 | E13: 2.3 yrs | F13: 8.42 | G13: 10.42 | H13: 4.09x | I13: 82.5% | J13: 408788.6
A14: 11 | B14: H8020 | C14: Himalayan 80-20 Fund | D14: 2024-01-14 | E14: 2.3 yrs | F14: 10 | G14: 11.37 | H14: 3.35x | I14: 68.7% | J14: 335300
A15: 12 | B15: NICGF2 | C15: NIC Asia Growth Fund II | D15: 2024-02-11 | E15: 2.2 yrs | F15: 9 | G15: 9.52 | H15: 1.06x | I15: 2.5% | J15: 105777.78
... A24: 21 | B24: RBBF40 | C24: RBB Focus 40 Fund | D24: 2026-01-18 | E24: 4 mo | F24: 9.43 | G24: 9.33 | H24: 0.99x | I24: -3.5% | J24: 98939.55
A26: Mutual Funds: 21 · Profitable: 18 · Loss: 3 · Avg CAGR: 33.2%

Sheet 🔀 Merger Relistings
A1: 🔀 NEPSE — Merger Relisted Companies Performance Tracker
A2: Companies relisted after merger · 11 entries · As of May 09, 2026 · Base investment NPR 100,000
A3: # | B3: Symbol | C3: Company Name | D3: Merged From (Entities) | E3: Listing Date | F3: Time Since | G3: Start Price (NPR) | H3: Current Price (NPR) | I3: Multiple | J3: CAGR (%) | K3: Current Value (NPR)
A4: =IF(B4<>"",ROW()-3,"") -> 1 | B4: DLBS | C4: Dhaulagiri Laghubitta Bittiya Sanstha | D4: DLBS + Khaptad Laghubitta | E4: 2022-10-23 | F4: 3.5 yrs | G4: 179.7 | H4: 1319 | I4: 7.34x | J4: 75.6% | K4: 734001.11
A5: =IF(B5<>"",ROW()-3,"") -> 2 | B5: SGIC | C5: Sanima GIC Insurance Ltd | D5: Sanima General + GIC Insurance | E5: 2023-01-23 | F5: 3.3 yrs | G5: 404.2 | H5: 462 | I5: 1.29x | J5: 8.1% | K5: 129183.61
A6: =IF(B6<>"",ROW()-3,"") -> 3 | B6: NIMB | C6: Nepal Investment Mega Bank Ltd | D6: MEGA + NIB | E6: 2023-02-23 | F6: 3.2 yrs | G6: 216 | H6: 199.7 | I6: 0.92x | J6: -2.4% | K6: 92453.7
A7: =IF(B7<>"",ROW()-3,"") -> 4 | B7: UNLB | C7: Unique Nepal Laghubitta Bittiya Sanstha | D7: UNLB + Ghodighoda Laghubitta | E7: 2023-02-28 | F7: 3.2 yrs | G7: 989.4 | H7: 1460 | I7: 1.48x | J7: 13.0% | K7: 147564.18
A8: =IF(B8<>"",ROW()-3,"") -> 5 | B8: MATRI | C8: Matribhumi Laghubitta Bittiya Sanstha | E8: 45517 | F8: 1.7 yrs | G8: 1406.2 | H8: 900 | I8: 0.64x | J8: -0.227 | K8: 64002.28
A9: =IF(B9<>"",ROW()-3,"") -> 6 | B9: CITY | C9: Citizens Bank International Ltd | D9: Citizens Bank + NCC Bank | E9: 2023-06-11 | F9: 2.9 yrs | G9: 122.2 | H9: 424 | I9: 3.77x | J9: 57.9% | K9: 624549.92
A10: =IF(B10<>"",ROW()-3,"") -> 7 | B10: HLI | C10: Himalayan Life Insurance Ltd | D10: Gurans Life + Prime Life + Union Life | E10: 2023-06-22 | F10: 2.9 yrs | G10: 381.1 | H10: 339 | I10: 1.04x | J10: 1.3% | K10: 103799.53
A11: =IF(B11<>"",ROW()-3,"") -> 8 | B11: NRM | C11: NRN Laghubitta Bittiya Sanstha | D11: National + Rural Microfinance merger | E11: 2023-08-06 | F11: 2.8 yrs | G11: 275.4 | H11: 392 | I11: 1.42x | J11: 13.7% | K11: 142338.42
A12: =IF(B12<>"",ROW()-3,"") -> 9 | B12: USHL | C12: Unnati Sahakarya Hydropower Ltd | D12: Unnati Sahakarya + merger | E12: 2023-08-13 | F12: 2.7 yrs | G12: 278.9 | H12: 640 | I12: 2.29x | J12: 35.5% | K12: 229472.93
A13: =IF(B13<>"",ROW()-3,"") -> 10 | B13: TSHL | C13: Tinau Sahakarya Hydropower Ltd | D13: Tewa Sahakarya + merger | E13: 2023-08-13 | F13: 2.7 yrs | G13: 280.5 | H13: 610 | I13: 2.17x | J13: 32.9% | K13: 217468.81
A14: =IF(B14<>"",ROW()-3,"") -> 11 | B14: LSL | C14: Laxmi Sunrise Bank Ltd | D14: Laxmi Bank + Sunrise Bank | E14: 2023-08-28 | F14: 2.7 yrs | G14: 181.2 | H14: 216.7 | I14: 1.48x | J14: 15.8% | K14: 148483.64
A15: =IF(B15<>"",ROW()-3,"") -> 12 | B15: MKCL | C15: Muktinath Krishi Company Ltd | D15: Muktinath Krishi + FPO relisting | E15: 2023-12-14 | F15: 2.4 yrs | G15: 196.6 | H15: 1290 | I15: 7.09x | J15: 126.3% | K15: 708860.63
A17: Merger Relistings: 12 · Profitable: 10 · Loss: 2 · Avg CAGR: ~30%

Sheet 🔵 Debentures
A1: 🔵 NEPSE New Listings — Debenture / Bond Performance Tracker
A2: Sorted oldest → newest · 17 debenture listings · As of May 09, 2026 · Base investment NPR 100,000
A3: # | B3: Symbol | C3: Debenture Name | D3: Issuing Bank / Company | E3: Listing Date | F3: Time Since IPO | G3: Issue Price (NPR) | H3: Current Price (NPR) | I3: Multiple | J3: CAGR (%) | K3: Current Value (NPR)
A4: 1 | B4: SBID83 | C4: Siddhartha Bank Debenture 2083 | D4: Siddhartha Bank Ltd | E4: 2022-10-16 | F4: 3.5 yrs | G4: 1000 | H4: 1075 | I4: 1.07x | J4: 2.1% | K4: 107500
A5: 2 | B5: PBLD87 | C5: Prabhu Bank Debenture 2087 | D5: Prabhu Bank Ltd | E5: 2022-11-30 | F5: 3.4 yrs | G5: 1000 | H5: 1107 | I5: 1.11x | J5: 3.0% | K5: 110700
A6: 3 | B6: CIZBD86 | C6: Citizens Bank Debenture 2086 | D6: Citizens Bank International Ltd | E6: 2023-07-10 | F6: 2.8 yrs | G6: 1040 | H6: 1198 | I6: 1.15x | J6: 5.2% | K6: 115192.31
A7: 4 | B7: HBLD86 | C7: Himalayan Bank Debenture 2086 | D7: Himalayan Bank Ltd | E7: 2023-12-18 | F7: 2.4 yrs | G7: 1000 | H7: 1148.4 | I7: 1.15x | J7: 6.0% | K7: 114840
A8: 5 | B8: RBBD83 | C8: Rastriya Banijya Bank Debenture 2083 | D8: Rastriya Banijya Bank | E8: 2023-12-20 | F8: 2.4 yrs | G8: 950 | H8: 1037 | I8: 1.09x | J8: 3.8% | K8: 109157.89
A9: 6 | B9: SBID89 | C9: Siddhartha Bank Debenture 2089 | D9: Siddhartha Bank Ltd | E9: 2024-01-03 | F9: 2.3 yrs | G9: 1000 | H9: 1140 | I9: 1.14x | J9: 5.8% | K9: 114000
A10: 7 | B10: MLBLD89 | C10: Machhapuchchhre Bank Debenture 2089 | D10: Machhapuchchhre Bank Ltd | E10: 2024-04-29 | F10: 2.0 yrs | G10: 1061.2 | H10: 1250 | I10: 1.18x | J10: 8.4% | K10: 117791.18
A11: 8 | B11: CIZBD90 | C11: Citizens Bank Debenture 2090 | D11: Citizens Bank International Ltd | E11: 2024-04-30 | F11: 2.0 yrs | G11: 1020 | H11: 1265 | I11: 1.24x | J11: 11.2% | K11: 124019.61
A12: 9 | B12: BOKD86KA | C12: Bank of Kathmandu Debenture 2086 (A) | D12: Bank of Kathmandu Ltd | E12: 2024-06-24 | F12: 1.7 yrs | G12: 1020 | H12: 1204 | I12: 1.18x | J12: 10.3% | K12: 118039.22
A13: 10 | B13: ICFCD88 | C13: ICFC Finance Debenture 2088 | D13: ICFC Finance Company Ltd | E13: 2025-03-09 | F13: 1.2 yrs | G13: 1100 | H13: 1155 | I13: 1.05x | J13: 4.3% | K13: 105000
A14: 11 | B14: EBLD91 | C14: Everest Bank Debenture 2091 | D14: Everest Bank Ltd | E14: 2025-05-21 | F14: 12 mo | G14: 1025 | H14: 1062 | I14: 1.04x | J14: 3.8% | K14: 103609.76
A15: 12 | B15: NIFRAGED | C15: Nifra Gorge Hydropower Debenture | D15: Nifra Gorge Hydropower Ltd | E15: 2025-07-15 | F15: 10 mo | G15: 1001 | H15: 1035.7 | I15: 1.03x | J15: 4.3% | K15: 103466.53
... A20: 17 | B20: NABILD2089 | C20: Nabil Bank Debenture 2089 | D20: Nabil Bank Ltd | E20: 2025-11-16 | F20: 6 mo | G20: 1069 | H20: 1060 | I20: 0.99x | J20: -1.8% | K20: 99158.09
A22: Debentures: 17 · Profitable: 15 · Loss: 2 · Avg CAGR: 5.1%

Sheet Promoter Shares
A1: 📈 NEPSE New Listings — Equity Performance Tracker
A2: Sorted oldest → newest · 77 equity listings · As of May 09, 2026 · Base investment NPR 100,000
A3: # | B3: Symbol | C3: Company Name | D3: Listing Date | E3: Time Since IPO | F3: Start Price (NPR) | G3: Current Price (NPR) | H3: Multiple | I3: CAGR (%) | J3: Current Value (NPR)
A4: 11 | B4: NIMBPO | C4: Nepal Investment Mega Bank Promoter Offer | D4: 2023-03-20 | E4: 3.1 yrs | F4: 111.3 | G4: 153.9 | H4: 1.38x | I4: 10.9% | J4: 138274.93
A6: Equities: 77 · Profitable: 72 · Loss: 5 · Avg CAGR: 761.4%
